RPython traceback:
  File "rpython_jit_metainterp.c", line 22541, in BlackholeInterpreter__resume_mainloop
  File "rpython_jit_metainterp.c", line 40172, in BlackholeInterpreter_handle_exception_in_frame
/opt/pypy3/site-packages/dask/dataframe/core.py:3370: UserWarning: 
You did not provide metadata, so Dask is running your function on a small dataset to guess output types. It is possible that Dask will guess incorrectly.
To provide an explicit output types or to silence this message, please provide the `meta=` keyword, as described in the map or apply function that you are using.
  Before: .apply(func)
  After:  .apply(func, meta=('title', 'object'))

  warnings.warn(meta_warning(meta))
Exception in thread Profile:
Traceback (most recent call last):
  File "/opt/pypy3/lib-python/3/threading.py", line 916, in _bootstrap_inner
    self.run()
  File "/opt/pypy3/lib-python/3/threading.py", line 864, in run
    self._target(*self._args, **self._kwargs)
  File "/opt/pypy3/site-packages/distributed/profile.py", line 268, in _watch
    process(frame, None, recent, omit=omit)
  File "/opt/pypy3/site-packages/distributed/profile.py", line 103, in process
    state = process(prev, frame, state, stop=stop)
  File "/opt/pypy3/site-packages/distributed/profile.py", line 103, in process
    state = process(prev, frame, state, stop=stop)
  File "/opt/pypy3/site-packages/distributed/profile.py", line 103, in process
    state = process(prev, frame, state, stop=stop)
  [Previous line repeated 2 more times]
  File "/opt/pypy3/site-packages/distributed/profile.py", line 99, in process
    prev = frame.f_back
SystemError: unexpected internal exception (please report a bug): <InvalidVirtualRef object at 0x7f67a898d168>; internal traceback was dumped to stderr

