/opt/pypy3/site-packages/distributed/node.py:155: UserWarning: Port 8787 is already in use.
Perhaps you already have a cluster running?
Hosting the HTTP server on port 46821 instead
  http_address["port"], self.http_server.port
RPython traceback:
  File "rpython_jit_metainterp.c", line 22541, in BlackholeInterpreter__resume_mainloop
  File "rpython_jit_metainterp.c", line 40172, in BlackholeInterpreter_handle_exception_in_frame
Exception in thread Profile:
Traceback (most recent call last):
  File "/opt/pypy3/lib-python/3/threading.py", line 916, in _bootstrap_inner
    self.run()
  File "/opt/pypy3/lib-python/3/threading.py", line 864, in run
    self._target(*self._args, **self._kwargs)
  File "/opt/pypy3/site-packages/distributed/profile.py", line 268, in _watch
    process(frame, None, recent, omit=omit)
  File "/opt/pypy3/site-packages/distributed/profile.py", line 103, in process
    state = process(prev, frame, state, stop=stop)
  File "/opt/pypy3/site-packages/distributed/profile.py", line 103, in process
    state = process(prev, frame, state, stop=stop)
  File "/opt/pypy3/site-packages/distributed/profile.py", line 99, in process
    prev = frame.f_back
SystemError: unexpected internal exception (please report a bug): <InvalidVirtualRef object at 0x7fab22da8168>; internal traceback was dumped to stderr

