distributed.worker - ERROR - Worker stream died during communication: tcp://127.0.0.1:34071
Traceback (most recent call last):
  File "/usr/local/lib/python3.6/site-packages/distributed/comm/core.py", line 319, in connect
    handshake = await asyncio.wait_for(comm.read(), time_left())
  File "/usr/local/lib/python3.6/asyncio/tasks.py", line 362, in wait_for
    raise futures.TimeoutError()
concurrent.futures._base.TimeoutError

The above exception was the direct cause of the following exception:

Traceback (most recent call last):
  File "/usr/local/lib/python3.6/site-packages/distributed/worker.py", line 2064, in gather_dep
    self.rpc, deps, worker, who=self.address
  File "/usr/local/lib/python3.6/site-packages/distributed/worker.py", line 3333, in get_data_from_worker
    return await retry_operation(_get_data, operation="get_data_from_worker")
  File "/usr/local/lib/python3.6/site-packages/distributed/utils_comm.py", line 389, in retry_operation
    operation=operation,
  File "/usr/local/lib/python3.6/site-packages/distributed/utils_comm.py", line 369, in retry
    return await coro()
  File "/usr/local/lib/python3.6/site-packages/distributed/worker.py", line 3310, in _get_data
    comm = await rpc.connect(worker)
  File "/usr/local/lib/python3.6/site-packages/distributed/core.py", line 1013, in connect
    **self.connection_args,
  File "/usr/local/lib/python3.6/site-packages/distributed/comm/core.py", line 326, in connect
    ) from exc
OSError: Timed out during handshake while connecting to tcp://127.0.0.1:34071 after 10 s
distributed.worker - ERROR - Worker stream died during communication: tcp://127.0.0.1:34071
Traceback (most recent call last):
  File "/usr/local/lib/python3.6/site-packages/distributed/comm/core.py", line 319, in connect
    handshake = await asyncio.wait_for(comm.read(), time_left())
  File "/usr/local/lib/python3.6/asyncio/tasks.py", line 362, in wait_for
    raise futures.TimeoutError()
concurrent.futures._base.TimeoutError

The above exception was the direct cause of the following exception:

Traceback (most recent call last):
  File "/usr/local/lib/python3.6/site-packages/distributed/worker.py", line 2064, in gather_dep
    self.rpc, deps, worker, who=self.address
  File "/usr/local/lib/python3.6/site-packages/distributed/worker.py", line 3333, in get_data_from_worker
    return await retry_operation(_get_data, operation="get_data_from_worker")
  File "/usr/local/lib/python3.6/site-packages/distributed/utils_comm.py", line 389, in retry_operation
    operation=operation,
  File "/usr/local/lib/python3.6/site-packages/distributed/utils_comm.py", line 369, in retry
    return await coro()
  File "/usr/local/lib/python3.6/site-packages/distributed/worker.py", line 3310, in _get_data
    comm = await rpc.connect(worker)
  File "/usr/local/lib/python3.6/site-packages/distributed/core.py", line 1013, in connect
    **self.connection_args,
  File "/usr/local/lib/python3.6/site-packages/distributed/comm/core.py", line 326, in connect
    ) from exc
OSError: Timed out during handshake while connecting to tcp://127.0.0.1:34071 after 10 s
distributed.worker - WARNING - Heartbeat to scheduler failed
