distributed.worker - ERROR - failed during get data with tcp://127.0.0.1:45543 -> tcp://127.0.0.1:44539
Traceback (most recent call last):
  File "/usr/local/lib/python3.6/site-packages/tornado/iostream.py", line 867, in _read_to_buffer
    bytes_read = self.read_from_fd(buf)
  File "/usr/local/lib/python3.6/site-packages/tornado/iostream.py", line 1140, in read_from_fd
    return self.socket.recv_into(buf, len(buf))
TimeoutError: [Errno 110] Connection timed out

The above exception was the direct cause of the following exception:

Traceback (most recent call last):
  File "/usr/local/lib/python3.6/site-packages/distributed/worker.py", line 1360, in get_data
    response = await comm.read(deserializers=serializers)
  File "/usr/local/lib/python3.6/site-packages/distributed/comm/tcp.py", line 205, in read
    convert_stream_closed_error(self, e)
  File "/usr/local/lib/python3.6/site-packages/distributed/comm/tcp.py", line 126, in convert_stream_closed_error
    ) from exc
distributed.comm.core.CommClosedError: in <closed TCP>: TimeoutError: [Errno 110] Connection timed out
distributed.worker - ERROR - Worker stream died during communication: tcp://127.0.0.1:45543
Traceback (most recent call last):
  File "/usr/local/lib/python3.6/site-packages/tornado/iostream.py", line 867, in _read_to_buffer
    bytes_read = self.read_from_fd(buf)
  File "/usr/local/lib/python3.6/site-packages/tornado/iostream.py", line 1140, in read_from_fd
    return self.socket.recv_into(buf, len(buf))
ConnectionResetError: [Errno 104] Connection reset by peer

The above exception was the direct cause of the following exception:

Traceback (most recent call last):
  File "/usr/local/lib/python3.6/site-packages/distributed/worker.py", line 2064, in gather_dep
    self.rpc, deps, worker, who=self.address
  File "/usr/local/lib/python3.6/site-packages/distributed/worker.py", line 3333, in get_data_from_worker
    return await retry_operation(_get_data, operation="get_data_from_worker")
  File "/usr/local/lib/python3.6/site-packages/distributed/utils_comm.py", line 389, in retry_operation
    operation=operation,
  File "/usr/local/lib/python3.6/site-packages/distributed/utils_comm.py", line 369, in retry
    return await coro()
  File "/usr/local/lib/python3.6/site-packages/distributed/worker.py", line 3320, in _get_data
    max_connections=max_connections,
  File "/usr/local/lib/python3.6/site-packages/distributed/core.py", line 644, in send_recv
    response = await comm.read(deserializers=deserializers)
  File "/usr/local/lib/python3.6/site-packages/distributed/comm/tcp.py", line 205, in read
    convert_stream_closed_error(self, e)
  File "/usr/local/lib/python3.6/site-packages/distributed/comm/tcp.py", line 126, in convert_stream_closed_error
    ) from exc
distributed.comm.core.CommClosedError: in <closed TCP>: ConnectionResetError: [Errno 104] Connection reset by peer
